2025-05-07 11:55:29,707 - uvicorn.error - ERROR - Traceback (most recent call last):
  File "C:\Users\User\AppData\Local\Programs\Python\Python312\Lib\site-packages\starlette\routing.py", line 686, in lifespan
    await receive()
  File "C:\Users\User\AppData\Local\Programs\Python\Python312\Lib\site-packages\uvicorn\lifespan\on.py", line 137, in receive
    return await self.receive_queue.get()
           ^^^^^^^^^^^^^^^^^^^^^^^^^^^^^^
  File "C:\Users\User\AppData\Local\Programs\Python\Python312\Lib\asyncio\queues.py", line 158, in get
    await getter
asyncio.exceptions.CancelledError

2025-06-02 17:25:59,670 - celery.backends.redis - ERROR - Connection to Redis lost: Retry (0/20) now.
2025-06-02 17:26:03,743 - celery.backends.redis - ERROR - Connection to Redis lost: Retry (1/20) in 1.00 second.
2025-06-02 17:26:08,797 - celery.backends.redis - ERROR - Connection to Redis lost: Retry (2/20) in 1.00 second.
2025-06-02 17:26:13,880 - celery.backends.redis - ERROR - Connection to Redis lost: Retry (3/20) in 1.00 second.
2025-06-02 17:26:18,933 - celery.backends.redis - ERROR - Connection to Redis lost: Retry (4/20) in 1.00 second.
2025-06-02 17:26:23,996 - celery.backends.redis - ERROR - Connection to Redis lost: Retry (5/20) in 1.00 second.
2025-06-02 17:26:29,060 - celery.backends.redis - ERROR - Connection to Redis lost: Retry (6/20) in 1.00 second.
2025-06-02 17:26:34,122 - celery.backends.redis - ERROR - Connection to Redis lost: Retry (7/20) in 1.00 second.
2025-06-02 17:26:39,183 - celery.backends.redis - ERROR - Connection to Redis lost: Retry (8/20) in 1.00 second.
2025-06-02 17:26:44,293 - celery.backends.redis - ERROR - Connection to Redis lost: Retry (9/20) in 1.00 second.
2025-06-02 17:26:49,372 - celery.backends.redis - ERROR - Connection to Redis lost: Retry (10/20) in 1.00 second.
2025-06-02 17:26:54,431 - celery.backends.redis - ERROR - Connection to Redis lost: Retry (11/20) in 1.00 second.
2025-06-02 17:26:59,512 - celery.backends.redis - ERROR - Connection to Redis lost: Retry (12/20) in 1.00 second.
2025-06-02 17:27:04,578 - celery.backends.redis - ERROR - Connection to Redis lost: Retry (13/20) in 1.00 second.
2025-06-02 17:27:09,653 - celery.backends.redis - ERROR - Connection to Redis lost: Retry (14/20) in 1.00 second.
2025-06-02 17:27:14,746 - celery.backends.redis - ERROR - Connection to Redis lost: Retry (15/20) in 1.00 second.
2025-06-02 17:27:19,809 - celery.backends.redis - ERROR - Connection to Redis lost: Retry (16/20) in 1.00 second.
2025-06-02 17:27:24,888 - celery.backends.redis - ERROR - Connection to Redis lost: Retry (17/20) in 1.00 second.
2025-06-02 17:27:29,959 - celery.backends.redis - ERROR - Connection to Redis lost: Retry (18/20) in 1.00 second.
2025-06-02 17:27:35,027 - celery.backends.redis - ERROR - Connection to Redis lost: Retry (19/20) in 1.00 second.
2025-06-02 17:27:40,097 - celery.backends.redis - CRITICAL - 
Retry limit exceeded while trying to reconnect to the Celery redis result store backend. The Celery application must be restarted.

2025-06-02 17:27:40,097 - github_webhook - ERROR - [github_1748856351_test-push-delivery-456] 处理 GitHub webhook 时出现意外错误: Error 10061 connecting to localhost:6379. 由于目标计算机积极拒绝，无法连接。.
Traceback (most recent call last):
  File "C:\Users\User\AppData\Local\Programs\Python\Python312\Lib\site-packages\redis\connection.py", line 264, in connect
    sock = self.retry.call_with_retry(
           ^^^^^^^^^^^^^^^^^^^^^^^^^^^
  File "C:\Users\User\AppData\Local\Programs\Python\Python312\Lib\site-packages\redis\retry.py", line 46, in call_with_retry
    return do()
           ^^^^
  File "C:\Users\User\AppData\Local\Programs\Python\Python312\Lib\site-packages\redis\connection.py", line 265, in <lambda>
    lambda: self._connect(), lambda error: self.disconnect(error)
            ^^^^^^^^^^^^^^^
  File "C:\Users\User\AppData\Local\Programs\Python\Python312\Lib\site-packages\redis\connection.py", line 627, in _connect
    raise err
  File "C:\Users\User\AppData\Local\Programs\Python\Python312\Lib\site-packages\redis\connection.py", line 615, in _connect
    sock.connect(socket_address)
ConnectionRefusedError: [WinError 10061] 由于目标计算机积极拒绝，无法连接。

During handling of the above exception, another exception occurred:

Traceback (most recent call last):
  File "C:\Users\User\AppData\Local\Programs\Python\Python312\Lib\site-packages\celery\backends\redis.py", line 127, in reconnect_on_error
    yield
  File "C:\Users\User\AppData\Local\Programs\Python\Python312\Lib\site-packages\celery\backends\redis.py", line 177, in _consume_from
    self._pubsub.subscribe(key)
  File "C:\Users\User\AppData\Local\Programs\Python\Python312\Lib\site-packages\redis\client.py", line 916, in subscribe
    ret_val = self.execute_command("SUBSCRIBE", *new_channels.keys())
              ^^^^^^^^^^^^^^^^^^^^^^^^^^^^^^^^^^^^^^^^^^^^^^^^^^^^^^^
  File "C:\Users\User\AppData\Local\Programs\Python\Python312\Lib\site-packages\redis\client.py", line 749, in execute_command
    self.connection = self.connection_pool.get_connection(
                      ^^^^^^^^^^^^^^^^^^^^^^^^^^^^^^^^^^^^
  File "C:\Users\User\AppData\Local\Programs\Python\Python312\Lib\site-packages\redis\connection.py", line 1086, in get_connection
    connection.connect()
  File "C:\Users\User\AppData\Local\Programs\Python\Python312\Lib\site-packages\redis\connection.py", line 270, in connect
    raise ConnectionError(self._error_message(e))
redis.exceptions.ConnectionError: Error 10061 connecting to localhost:6379. 由于目标计算机积极拒绝，无法连接。.

During handling of the above exception, another exception occurred:

Traceback (most recent call last):
  File "C:\Users\User\AppData\Local\Programs\Python\Python312\Lib\site-packages\redis\connection.py", line 264, in connect
    sock = self.retry.call_with_retry(
           ^^^^^^^^^^^^^^^^^^^^^^^^^^^
  File "C:\Users\User\AppData\Local\Programs\Python\Python312\Lib\site-packages\redis\retry.py", line 46, in call_with_retry
    return do()
           ^^^^
  File "C:\Users\User\AppData\Local\Programs\Python\Python312\Lib\site-packages\redis\connection.py", line 265, in <lambda>
    lambda: self._connect(), lambda error: self.disconnect(error)
            ^^^^^^^^^^^^^^^
  File "C:\Users\User\AppData\Local\Programs\Python\Python312\Lib\site-packages\redis\connection.py", line 627, in _connect
    raise err
  File "C:\Users\User\AppData\Local\Programs\Python\Python312\Lib\site-packages\redis\connection.py", line 615, in _connect
    sock.connect(socket_address)
ConnectionRefusedError: [WinError 10061] 由于目标计算机积极拒绝，无法连接。

During handling of the above exception, another exception occurred:

Traceback (most recent call last):
  File "C:\Users\User\AppData\Local\Programs\Python\Python312\Lib\site-packages\kombu\connection.py", line 472, in _reraise_as_library_errors
    yield
  File "C:\Users\User\AppData\Local\Programs\Python\Python312\Lib\site-packages\celery\app\base.py", line 797, in send_task
    self.backend.on_task_call(P, task_id)
  File "C:\Users\User\AppData\Local\Programs\Python\Python312\Lib\site-packages\celery\backends\redis.py", line 373, in on_task_call
    self.result_consumer.consume_from(task_id)
  File "C:\Users\User\AppData\Local\Programs\Python\Python312\Lib\site-packages\celery\backends\redis.py", line 169, in consume_from
    return self.start(task_id)
           ^^^^^^^^^^^^^^^^^^^
  File "C:\Users\User\AppData\Local\Programs\Python\Python312\Lib\site-packages\celery\backends\redis.py", line 147, in start
    self._consume_from(initial_task_id)
  File "C:\Users\User\AppData\Local\Programs\Python\Python312\Lib\site-packages\celery\backends\redis.py", line 176, in _consume_from
    with self.reconnect_on_error():
         ^^^^^^^^^^^^^^^^^^^^^^^^^
  File "C:\Users\User\AppData\Local\Programs\Python\Python312\Lib\contextlib.py", line 158, in __exit__
    self.gen.throw(value)
  File "C:\Users\User\AppData\Local\Programs\Python\Python312\Lib\site-packages\celery\backends\redis.py", line 130, in reconnect_on_error
    self._ensure(self._reconnect_pubsub, ())
  File "C:\Users\User\AppData\Local\Programs\Python\Python312\Lib\site-packages\celery\backends\redis.py", line 384, in ensure
    return retry_over_time(
           ^^^^^^^^^^^^^^^^
  File "C:\Users\User\AppData\Local\Programs\Python\Python312\Lib\site-packages\kombu\utils\functional.py", line 318, in retry_over_time
    return fun(*args, **kwargs)
           ^^^^^^^^^^^^^^^^^^^^
  File "C:\Users\User\AppData\Local\Programs\Python\Python312\Lib\site-packages\celery\backends\redis.py", line 106, in _reconnect_pubsub
    metas = self.backend.client.mget(self.subscribed_to)
            ^^^^^^^^^^^^^^^^^^^^^^^^^^^^^^^^^^^^^^^^^^^^
  File "C:\Users\User\AppData\Local\Programs\Python\Python312\Lib\site-packages\redis\commands\core.py", line 2015, in mget
    return self.execute_command("MGET", *args, **options)
           ^^^^^^^^^^^^^^^^^^^^^^^^^^^^^^^^^^^^^^^^^^^^^^
  File "C:\Users\User\AppData\Local\Programs\Python\Python312\Lib\site-packages\redis\client.py", line 533, in execute_command
    conn = self.connection or pool.get_connection(command_name, **options)
                              ^^^^^^^^^^^^^^^^^^^^^^^^^^^^^^^^^^^^^^^^^^^^
  File "C:\Users\User\AppData\Local\Programs\Python\Python312\Lib\site-packages\redis\connection.py", line 1086, in get_connection
    connection.connect()
  File "C:\Users\User\AppData\Local\Programs\Python\Python312\Lib\site-packages\redis\connection.py", line 270, in connect
    raise ConnectionError(self._error_message(e))
redis.exceptions.ConnectionError: Error 10061 connecting to localhost:6379. 由于目标计算机积极拒绝，无法连接。.

The above exception was the direct cause of the following exception:

Traceback (most recent call last):
  File "D:\Personal\Script\GE\jacocoApi\github_webhook.py", line 217, in github_webhook_handler
    task = celery_app.send_task(
           ^^^^^^^^^^^^^^^^^^^^^
  File "C:\Users\User\AppData\Local\Programs\Python\Python312\Lib\site-packages\celery\app\base.py", line 795, in send_task
    with P.connection._reraise_as_library_errors():
         ^^^^^^^^^^^^^^^^^^^^^^^^^^^^^^^^^^^^^^^^^
  File "C:\Users\User\AppData\Local\Programs\Python\Python312\Lib\contextlib.py", line 158, in __exit__
    self.gen.throw(value)
  File "C:\Users\User\AppData\Local\Programs\Python\Python312\Lib\site-packages\kombu\connection.py", line 476, in _reraise_as_library_errors
    raise ConnectionError(str(exc)) from exc
kombu.exceptions.OperationalError: Error 10061 connecting to localhost:6379. 由于目标计算机积极拒绝，无法连接。.
