2025-05-07 11:37:03,200 - uvicorn.access - INFO - 127.0.0.1:14404 - "GET /health HTTP/1.1" 200
2025-05-07 11:37:03,447 - uvicorn.access - INFO - 127.0.0.1:14404 - "GET /favicon.ico HTTP/1.1" 404
2025-05-07 11:37:08,187 - uvicorn.access - INFO - 127.0.0.1:14404 - "GET /metrics HTTP/1.1" 200
2025-05-07 11:37:12,931 - uvicorn.access - INFO - 127.0.0.1:14404 - "GET /docs HTTP/1.1" 200
2025-05-07 11:54:20,441 - uvicorn.access - INFO - 127.0.0.1:18227 - "GET / HTTP/1.1" 404
2025-05-07 11:55:19,663 - uvicorn.access - INFO - 127.0.0.1:18228 - "GET / HTTP/1.1" 404
2025-05-07 11:55:24,586 - uvicorn.access - INFO - 127.0.0.1:18228 - "GET /health HTTP/1.1" 200
2025-06-02 17:24:52,264 - uvicorn.access - INFO - 127.0.0.1:30142 - "GET /health HTTP/1.1" 200
2025-06-02 17:25:06,872 - uvicorn.access - INFO - 127.0.0.1:30164 - "GET /github/test HTTP/1.1" 200
2025-06-02 17:25:11,765 - uvicorn.access - INFO - 127.0.0.1:30184 - "GET /docs HTTP/1.1" 200
2025-06-02 17:25:17,377 - uvicorn.access - INFO - 127.0.0.1:30185 - "GET /docs HTTP/1.1" 200
2025-06-02 17:25:26,813 - github_webhook - INFO - [github_1748856326_test-ping-delivery-123] 收到 GitHub webhook: ping
2025-06-02 17:25:26,815 - github_webhook - WARNING - [github_1748856326_test-ping-delivery-123] GitHub webhook 签名验证失败
2025-06-02 17:25:26,816 - uvicorn.access - INFO - 127.0.0.1:30219 - "POST /github/webhook HTTP/1.1" 401
2025-06-02 17:25:28,845 - github_webhook - INFO - [github_1748856328_test-push-delivery-456] 收到 GitHub webhook: push
2025-06-02 17:25:28,846 - github_webhook - WARNING - [github_1748856328_test-push-delivery-456] GitHub webhook 签名验证失败
2025-06-02 17:25:28,847 - uvicorn.access - INFO - 127.0.0.1:30221 - "POST /github/webhook HTTP/1.1" 401
2025-06-02 17:25:30,897 - uvicorn.access - INFO - 127.0.0.1:30225 - "GET /github/test HTTP/1.1" 200
2025-06-02 17:25:35,041 - uvicorn.access - INFO - 127.0.0.1:30187 - "GET /docs HTTP/1.1" 200
2025-06-02 17:25:38,026 - uvicorn.access - INFO - 127.0.0.1:30187 - "GET /doc HTTP/1.1" 404
2025-06-02 17:25:38,078 - uvicorn.access - INFO - 127.0.0.1:30187 - "GET /favicon.ico HTTP/1.1" 404
2025-06-02 17:25:49,413 - github_webhook - INFO - [github_1748856349_test-ping-delivery-123] 收到 GitHub webhook: ping
2025-06-02 17:25:49,414 - github_webhook - INFO - [github_1748856349_test-ping-delivery-123] GitHub ping 事件
2025-06-02 17:25:49,415 - uvicorn.access - INFO - 127.0.0.1:30272 - "POST /github/webhook HTTP/1.1" 200
2025-06-02 17:25:51,449 - github_webhook - INFO - [github_1748856351_test-push-delivery-456] 收到 GitHub webhook: push
2025-06-02 17:25:59,670 - celery.backends.redis - ERROR - Connection to Redis lost: Retry (0/20) now.
2025-06-02 17:26:03,743 - celery.backends.redis - ERROR - Connection to Redis lost: Retry (1/20) in 1.00 second.
2025-06-02 17:26:08,797 - celery.backends.redis - ERROR - Connection to Redis lost: Retry (2/20) in 1.00 second.
2025-06-02 17:26:13,880 - celery.backends.redis - ERROR - Connection to Redis lost: Retry (3/20) in 1.00 second.
2025-06-02 17:26:18,933 - celery.backends.redis - ERROR - Connection to Redis lost: Retry (4/20) in 1.00 second.
2025-06-02 17:26:23,996 - celery.backends.redis - ERROR - Connection to Redis lost: Retry (5/20) in 1.00 second.
2025-06-02 17:26:29,060 - celery.backends.redis - ERROR - Connection to Redis lost: Retry (6/20) in 1.00 second.
2025-06-02 17:26:34,122 - celery.backends.redis - ERROR - Connection to Redis lost: Retry (7/20) in 1.00 second.
2025-06-02 17:26:39,183 - celery.backends.redis - ERROR - Connection to Redis lost: Retry (8/20) in 1.00 second.
2025-06-02 17:26:44,293 - celery.backends.redis - ERROR - Connection to Redis lost: Retry (9/20) in 1.00 second.
2025-06-02 17:26:49,372 - celery.backends.redis - ERROR - Connection to Redis lost: Retry (10/20) in 1.00 second.
2025-06-02 17:26:54,431 - celery.backends.redis - ERROR - Connection to Redis lost: Retry (11/20) in 1.00 second.
2025-06-02 17:26:59,512 - celery.backends.redis - ERROR - Connection to Redis lost: Retry (12/20) in 1.00 second.
2025-06-02 17:27:04,578 - celery.backends.redis - ERROR - Connection to Redis lost: Retry (13/20) in 1.00 second.
2025-06-02 17:27:09,653 - celery.backends.redis - ERROR - Connection to Redis lost: Retry (14/20) in 1.00 second.
2025-06-02 17:27:14,746 - celery.backends.redis - ERROR - Connection to Redis lost: Retry (15/20) in 1.00 second.
2025-06-02 17:27:19,809 - celery.backends.redis - ERROR - Connection to Redis lost: Retry (16/20) in 1.00 second.
2025-06-02 17:27:24,888 - celery.backends.redis - ERROR - Connection to Redis lost: Retry (17/20) in 1.00 second.
2025-06-02 17:27:29,959 - celery.backends.redis - ERROR - Connection to Redis lost: Retry (18/20) in 1.00 second.
2025-06-02 17:27:35,027 - celery.backends.redis - ERROR - Connection to Redis lost: Retry (19/20) in 1.00 second.
2025-06-02 17:27:40,097 - celery.backends.redis - CRITICAL - 
Retry limit exceeded while trying to reconnect to the Celery redis result store backend. The Celery application must be restarted.

2025-06-02 17:27:40,097 - github_webhook - ERROR - [github_1748856351_test-push-delivery-456] 处理 GitHub webhook 时出现意外错误: Error 10061 connecting to localhost:6379. 由于目标计算机积极拒绝，无法连接。.
Traceback (most recent call last):
  File "C:\Users\User\AppData\Local\Programs\Python\Python312\Lib\site-packages\redis\connection.py", line 264, in connect
    sock = self.retry.call_with_retry(
           ^^^^^^^^^^^^^^^^^^^^^^^^^^^
  File "C:\Users\User\AppData\Local\Programs\Python\Python312\Lib\site-packages\redis\retry.py", line 46, in call_with_retry
    return do()
           ^^^^
  File "C:\Users\User\AppData\Local\Programs\Python\Python312\Lib\site-packages\redis\connection.py", line 265, in <lambda>
    lambda: self._connect(), lambda error: self.disconnect(error)
            ^^^^^^^^^^^^^^^
  File "C:\Users\User\AppData\Local\Programs\Python\Python312\Lib\site-packages\redis\connection.py", line 627, in _connect
    raise err
  File "C:\Users\User\AppData\Local\Programs\Python\Python312\Lib\site-packages\redis\connection.py", line 615, in _connect
    sock.connect(socket_address)
ConnectionRefusedError: [WinError 10061] 由于目标计算机积极拒绝，无法连接。

During handling of the above exception, another exception occurred:

Traceback (most recent call last):
  File "C:\Users\User\AppData\Local\Programs\Python\Python312\Lib\site-packages\celery\backends\redis.py", line 127, in reconnect_on_error
    yield
  File "C:\Users\User\AppData\Local\Programs\Python\Python312\Lib\site-packages\celery\backends\redis.py", line 177, in _consume_from
    self._pubsub.subscribe(key)
  File "C:\Users\User\AppData\Local\Programs\Python\Python312\Lib\site-packages\redis\client.py", line 916, in subscribe
    ret_val = self.execute_command("SUBSCRIBE", *new_channels.keys())
              ^^^^^^^^^^^^^^^^^^^^^^^^^^^^^^^^^^^^^^^^^^^^^^^^^^^^^^^
  File "C:\Users\User\AppData\Local\Programs\Python\Python312\Lib\site-packages\redis\client.py", line 749, in execute_command
    self.connection = self.connection_pool.get_connection(
                      ^^^^^^^^^^^^^^^^^^^^^^^^^^^^^^^^^^^^
  File "C:\Users\User\AppData\Local\Programs\Python\Python312\Lib\site-packages\redis\connection.py", line 1086, in get_connection
    connection.connect()
  File "C:\Users\User\AppData\Local\Programs\Python\Python312\Lib\site-packages\redis\connection.py", line 270, in connect
    raise ConnectionError(self._error_message(e))
redis.exceptions.ConnectionError: Error 10061 connecting to localhost:6379. 由于目标计算机积极拒绝，无法连接。.

During handling of the above exception, another exception occurred:

Traceback (most recent call last):
  File "C:\Users\User\AppData\Local\Programs\Python\Python312\Lib\site-packages\redis\connection.py", line 264, in connect
    sock = self.retry.call_with_retry(
           ^^^^^^^^^^^^^^^^^^^^^^^^^^^
  File "C:\Users\User\AppData\Local\Programs\Python\Python312\Lib\site-packages\redis\retry.py", line 46, in call_with_retry
    return do()
           ^^^^
  File "C:\Users\User\AppData\Local\Programs\Python\Python312\Lib\site-packages\redis\connection.py", line 265, in <lambda>
    lambda: self._connect(), lambda error: self.disconnect(error)
            ^^^^^^^^^^^^^^^
  File "C:\Users\User\AppData\Local\Programs\Python\Python312\Lib\site-packages\redis\connection.py", line 627, in _connect
    raise err
  File "C:\Users\User\AppData\Local\Programs\Python\Python312\Lib\site-packages\redis\connection.py", line 615, in _connect
    sock.connect(socket_address)
ConnectionRefusedError: [WinError 10061] 由于目标计算机积极拒绝，无法连接。

During handling of the above exception, another exception occurred:

Traceback (most recent call last):
  File "C:\Users\User\AppData\Local\Programs\Python\Python312\Lib\site-packages\kombu\connection.py", line 472, in _reraise_as_library_errors
    yield
  File "C:\Users\User\AppData\Local\Programs\Python\Python312\Lib\site-packages\celery\app\base.py", line 797, in send_task
    self.backend.on_task_call(P, task_id)
  File "C:\Users\User\AppData\Local\Programs\Python\Python312\Lib\site-packages\celery\backends\redis.py", line 373, in on_task_call
    self.result_consumer.consume_from(task_id)
  File "C:\Users\User\AppData\Local\Programs\Python\Python312\Lib\site-packages\celery\backends\redis.py", line 169, in consume_from
    return self.start(task_id)
           ^^^^^^^^^^^^^^^^^^^
  File "C:\Users\User\AppData\Local\Programs\Python\Python312\Lib\site-packages\celery\backends\redis.py", line 147, in start
    self._consume_from(initial_task_id)
  File "C:\Users\User\AppData\Local\Programs\Python\Python312\Lib\site-packages\celery\backends\redis.py", line 176, in _consume_from
    with self.reconnect_on_error():
         ^^^^^^^^^^^^^^^^^^^^^^^^^
  File "C:\Users\User\AppData\Local\Programs\Python\Python312\Lib\contextlib.py", line 158, in __exit__
    self.gen.throw(value)
  File "C:\Users\User\AppData\Local\Programs\Python\Python312\Lib\site-packages\celery\backends\redis.py", line 130, in reconnect_on_error
    self._ensure(self._reconnect_pubsub, ())
  File "C:\Users\User\AppData\Local\Programs\Python\Python312\Lib\site-packages\celery\backends\redis.py", line 384, in ensure
    return retry_over_time(
           ^^^^^^^^^^^^^^^^
  File "C:\Users\User\AppData\Local\Programs\Python\Python312\Lib\site-packages\kombu\utils\functional.py", line 318, in retry_over_time
    return fun(*args, **kwargs)
           ^^^^^^^^^^^^^^^^^^^^
  File "C:\Users\User\AppData\Local\Programs\Python\Python312\Lib\site-packages\celery\backends\redis.py", line 106, in _reconnect_pubsub
    metas = self.backend.client.mget(self.subscribed_to)
            ^^^^^^^^^^^^^^^^^^^^^^^^^^^^^^^^^^^^^^^^^^^^
  File "C:\Users\User\AppData\Local\Programs\Python\Python312\Lib\site-packages\redis\commands\core.py", line 2015, in mget
    return self.execute_command("MGET", *args, **options)
           ^^^^^^^^^^^^^^^^^^^^^^^^^^^^^^^^^^^^^^^^^^^^^^
  File "C:\Users\User\AppData\Local\Programs\Python\Python312\Lib\site-packages\redis\client.py", line 533, in execute_command
    conn = self.connection or pool.get_connection(command_name, **options)
                              ^^^^^^^^^^^^^^^^^^^^^^^^^^^^^^^^^^^^^^^^^^^^
  File "C:\Users\User\AppData\Local\Programs\Python\Python312\Lib\site-packages\redis\connection.py", line 1086, in get_connection
    connection.connect()
  File "C:\Users\User\AppData\Local\Programs\Python\Python312\Lib\site-packages\redis\connection.py", line 270, in connect
    raise ConnectionError(self._error_message(e))
redis.exceptions.ConnectionError: Error 10061 connecting to localhost:6379. 由于目标计算机积极拒绝，无法连接。.

The above exception was the direct cause of the following exception:

Traceback (most recent call last):
  File "D:\Personal\Script\GE\jacocoApi\github_webhook.py", line 217, in github_webhook_handler
    task = celery_app.send_task(
           ^^^^^^^^^^^^^^^^^^^^^
  File "C:\Users\User\AppData\Local\Programs\Python\Python312\Lib\site-packages\celery\app\base.py", line 795, in send_task
    with P.connection._reraise_as_library_errors():
         ^^^^^^^^^^^^^^^^^^^^^^^^^^^^^^^^^^^^^^^^^
  File "C:\Users\User\AppData\Local\Programs\Python\Python312\Lib\contextlib.py", line 158, in __exit__
    self.gen.throw(value)
  File "C:\Users\User\AppData\Local\Programs\Python\Python312\Lib\site-packages\kombu\connection.py", line 476, in _reraise_as_library_errors
    raise ConnectionError(str(exc)) from exc
kombu.exceptions.OperationalError: Error 10061 connecting to localhost:6379. 由于目标计算机积极拒绝，无法连接。.
2025-06-02 17:27:40,153 - uvicorn.access - INFO - 127.0.0.1:30275 - "POST /github/webhook HTTP/1.1" 500
2025-06-03 10:38:35,554 - github_webhook - INFO - [github_1748918315_unknown] 收到 GitHub webhook: None
2025-06-03 10:38:35,555 - github_webhook - WARNING - [github_1748918315_unknown] GitHub webhook 签名验证失败
2025-06-03 10:38:35,557 - uvicorn.access - INFO - 127.0.0.1:59245 - "POST /github/webhook HTTP/1.1" 401
2025-06-03 10:38:37,595 - github_webhook - INFO - [github_1748918317_unknown] 收到 GitHub webhook: None
2025-06-03 10:38:37,596 - github_webhook - WARNING - [github_1748918317_unknown] GitHub webhook 签名验证失败
2025-06-03 10:38:37,596 - uvicorn.access - INFO - 127.0.0.1:59247 - "POST /github/webhook HTTP/1.1" 401
2025-06-03 10:39:41,214 - github_webhook - INFO - [github_1748918381_unknown] 收到 GitHub webhook: None
2025-06-03 10:39:41,214 - github_webhook - WARNING - [github_1748918381_unknown] GitHub webhook 签名验证失败
2025-06-03 10:39:41,214 - uvicorn.access - INFO - 127.0.0.1:59318 - "POST /github/webhook HTTP/1.1" 401
2025-06-03 10:39:43,279 - github_webhook - INFO - [github_1748918383_unknown] 收到 GitHub webhook: None
2025-06-03 10:39:43,279 - github_webhook - WARNING - [github_1748918383_unknown] GitHub webhook 签名验证失败
2025-06-03 10:39:43,279 - uvicorn.access - INFO - 127.0.0.1:59320 - "POST /github/webhook HTTP/1.1" 401
2025-06-03 10:40:26,790 - uvicorn.access - INFO - 127.0.0.1:59373 - "GET /health HTTP/1.1" 200
2025-06-03 10:40:28,855 - github_webhook - INFO - [github_1748918428_unknown] 收到 GitHub webhook: None
2025-06-03 10:40:28,856 - github_webhook - WARNING - [github_1748918428_unknown] GitHub webhook 签名验证失败
2025-06-03 10:40:28,856 - uvicorn.access - INFO - 127.0.0.1:59378 - "POST /github/webhook HTTP/1.1" 401
2025-06-03 10:40:58,627 - uvicorn.access - INFO - 127.0.0.1:59409 - "GET /health HTTP/1.1" 200
2025-06-03 10:41:22,282 - github_webhook - INFO - [github_1748918482_unknown] 收到 GitHub webhook: ping
2025-06-03 10:41:22,283 - github_webhook - WARNING - [github_1748918482_unknown] GitHub webhook 签名验证失败
2025-06-03 10:41:22,283 - uvicorn.access - INFO - 127.0.0.1:59461 - "POST /github/webhook HTTP/1.1" 401
2025-06-03 10:41:24,326 - github_webhook - INFO - [github_1748918484_unknown] 收到 GitHub webhook: push
2025-06-03 10:41:24,327 - github_webhook - WARNING - [github_1748918484_unknown] GitHub webhook 签名验证失败
2025-06-03 10:41:24,327 - uvicorn.access - INFO - 127.0.0.1:59466 - "POST /github/webhook HTTP/1.1" 401
2025-06-03 10:46:35,101 - uvicorn.access - INFO - 127.0.0.1:59810 - "GET /health HTTP/1.1" 200
2025-06-03 10:46:37,148 - uvicorn.access - INFO - 127.0.0.1:59813 - "GET /health HTTP/1.1" 200
2025-06-03 10:46:39,208 - uvicorn.access - INFO - 127.0.0.1:59816 - "GET /docs HTTP/1.1" 200
2025-06-03 10:46:41,297 - uvicorn.access - INFO - 127.0.0.1:59821 - "GET /openapi.json HTTP/1.1" 200
2025-06-03 10:46:43,347 - uvicorn.access - INFO - 127.0.0.1:59824 - "GET /github/test HTTP/1.1" 200
2025-06-03 10:46:45,392 - github_webhook - INFO - [github_1748918805_unknown] 收到 GitHub webhook: None
2025-06-03 10:46:45,393 - github_webhook - WARNING - [github_1748918805_unknown] GitHub webhook 签名验证失败
2025-06-03 10:46:45,393 - uvicorn.access - INFO - 127.0.0.1:59827 - "POST /github/webhook HTTP/1.1" 401
2025-06-03 10:46:47,456 - github_webhook - INFO - [github_1748918807_unknown] 收到 GitHub webhook: None
2025-06-03 10:46:47,456 - github_webhook - WARNING - [github_1748918807_unknown] GitHub webhook 签名验证失败
2025-06-03 10:46:47,457 - uvicorn.access - INFO - 127.0.0.1:59830 - "POST /github/webhook HTTP/1.1" 401
2025-06-03 10:46:49,503 - uvicorn.access - INFO - 127.0.0.1:59836 - "POST /webhook HTTP/1.1" 404
2025-06-03 10:46:51,565 - uvicorn.access - INFO - 127.0.0.1:59841 - "POST /scan-trigger HTTP/1.1" 404
2025-06-03 10:46:53,612 - uvicorn.access - INFO - 127.0.0.1:59843 - "POST /api/webhook HTTP/1.1" 404
2025-06-03 10:47:20,392 - uvicorn.access - INFO - 127.0.0.1:59887 - "GET /health HTTP/1.1" 200
2025-06-03 10:47:22,457 - uvicorn.access - INFO - 127.0.0.1:59890 - "GET /health HTTP/1.1" 200
2025-06-03 10:47:24,502 - uvicorn.access - INFO - 127.0.0.1:59894 - "GET /docs HTTP/1.1" 200
2025-06-03 10:47:26,561 - uvicorn.access - INFO - 127.0.0.1:59907 - "GET /openapi.json HTTP/1.1" 200
2025-06-03 10:47:28,608 - uvicorn.access - INFO - 127.0.0.1:59913 - "GET /github/test HTTP/1.1" 200
2025-06-03 10:47:30,668 - github_webhook - INFO - [github_1748918850_unknown] 收到 GitHub webhook: None
2025-06-03 10:47:30,669 - github_webhook - WARNING - [github_1748918850_unknown] GitHub webhook 签名验证失败
2025-06-03 10:47:30,669 - uvicorn.access - INFO - 127.0.0.1:59922 - "POST /github/webhook HTTP/1.1" 401
2025-06-03 10:47:32,720 - github_webhook - INFO - [github_1748918852_unknown] 收到 GitHub webhook: None
2025-06-03 10:47:32,720 - github_webhook - WARNING - [github_1748918852_unknown] GitHub webhook 签名验证失败
2025-06-03 10:47:32,720 - uvicorn.access - INFO - 127.0.0.1:59928 - "POST /github/webhook HTTP/1.1" 401
2025-06-03 10:47:34,763 - uvicorn.access - INFO - 127.0.0.1:59933 - "POST /webhook HTTP/1.1" 404
2025-06-03 10:47:36,821 - uvicorn.access - INFO - 127.0.0.1:59939 - "POST /scan-trigger HTTP/1.1" 404
2025-06-03 10:47:38,867 - uvicorn.access - INFO - 127.0.0.1:59945 - "POST /api/webhook HTTP/1.1" 404
2025-06-03 10:48:39,516 - uvicorn.access - INFO - 127.0.0.1:10076 - "POST /github/webhook-no-auth HTTP/1.1" 404
2025-06-03 11:02:17,149 - github_webhook - INFO - [noauth_1748919737_1758676329888] 收到无认证 webhook 请求
2025-06-03 11:02:17,152 - github_webhook - INFO - [noauth_1748919737_1758676329888] 收到负载: {
  "object_kind": "push",
  "ref": "refs/heads/develop",
  "user_name": "Kian",
  "project": {
    "name": "jacocoTest"
  },
  "commits": [
    {
      "id": "abc123def456",
      "message": "Fix login bug"
    }
  ]
}
2025-06-03 11:02:17,152 - github_webhook - WARNING - GitLab payload 中未找到完整仓库 URL，使用构造的 URL: https://gitlab.com/user/jacocoTest.git
2025-06-03 11:02:17,153 - github_webhook - INFO - [noauth_1748919737_1758676329888] 解析结果: repo_url=https://gitlab.com/user/jacocoTest.git, commit_id=abc123def456, branch_name=develop, event_type=push
2025-06-03 11:02:17,153 - github_webhook - INFO - [noauth_1748919737_1758676329888] 模拟 JaCoCo 扫描任务: task_noauth_1748919737_1758676329888 用于 jacocoTest
2025-06-03 11:02:17,154 - uvicorn.access - INFO - 127.0.0.1:10931 - "POST /github/webhook-no-auth HTTP/1.1" 200
