2025-05-07 11:55:29,707 - uvicorn.error - ERROR - Traceback (most recent call last):
  File "C:\Users\User\AppData\Local\Programs\Python\Python312\Lib\site-packages\starlette\routing.py", line 686, in lifespan
    await receive()
  File "C:\Users\User\AppData\Local\Programs\Python\Python312\Lib\site-packages\uvicorn\lifespan\on.py", line 137, in receive
    return await self.receive_queue.get()
           ^^^^^^^^^^^^^^^^^^^^^^^^^^^^^^
  File "C:\Users\User\AppData\Local\Programs\Python\Python312\Lib\asyncio\queues.py", line 158, in get
    await getter
asyncio.exceptions.CancelledError

